Workbook

Sheet Unified KPI
A1: WR — Kavach Unified KPI
A2: Period: Jun15 - Jun21 (custom) · all locomotives · one combined row
A4: Month | B4: Zone | C4: Section | D4: No Of Trips | E4: Total KMs Run On Kavach | F4: Availability (FS+OS) | G4: Total EB | H4: EB (Valid Trips) | I4: EB (Non-Valid Trips) | J4: EB per Trip | K4: EB per KM | L4: EB per 100 KM | M4: EB per Trip per 1000 KM | N4: Total Mode Degradation | O4: Mode Degradation per Trip | P4: Mode Degradation per KM | Q4: Mode Degradation per Trip per 100 KM | R4: Mode Degradation per 100 KM | S4: Undesirable EB | T4: UNIFIED KPI
A5: Jun15 - Jun21 (custom) | B5: WR | C5: 24000_ADI to 24051_BRC | D5: ='Daily Breakdown'!C279 | E5: ='Daily Breakdown'!D279 | F5: ='Daily Breakdown'!G279 | G5: ='Daily Breakdown'!H279 | H5: ='Daily Breakdown'!I279 | I5: ='Daily Breakdown'!J279 | J5: =IFERROR(G5/D5,0) | K5: =IFERROR(G5/E5,0) | L5: =IFERROR(G5/E5*100,0) | M5: =IFERROR(G5/(D5*E5/1000),0) | N5: ='Daily Breakdown'!K279 | O5: =IFERROR(N5/D5,0) | P5: =IFERROR(N5/E5,0) | Q5: =IFERROR(N5/(D5*E5/100),0) | R5: =IFERROR(N5/E5*100,0) | S5: 19 | T5: =ROUND(F5*(1-M5)*(1-Q5),2)

Sheet Daily Breakdown
A1: Daily Breakdown — by day and locomotive (all locos)
A2: Availability base excludes locos with FS+OS pkts = 0 (they are still listed; only the Total-pkts availability base drops them).
A3: Date | B3: Loco ID | C3: No of Trips | D3: Total KMs | E3: FS+OS pkts | F3: Total pkts | G3: Availability (FS+OS) | H3: Total EB | I3: EB (Valid) | J3: EB (Non-Valid) | K3: Mode Degradation
A4: 15 Jun | B4: 30533 | C4: 1 | D4: 93.32 | E4: 9062 | F4: 9378 | G4: =IF(F4=0,0,E4/F4*100) | H4: 0 | I4: 0 | J4: 0 | K4: 4
A5: 15 Jun | B5: 30791 | C5: 1 | D5: 93.91 | E5: 5664 | F5: 6816 | G5: =IF(F5=0,0,E5/F5*100) | H5: 0 | I5: 0 | J5: 0 | K5: 4
A6: 15 Jun | B6: 37955 | C6: 1 | D6: 93.32 | E6: 6281 | F6: 6421 | G6: =IF(F6=0,0,E6/F6*100) | H6: 0 | I6: 0 | J6: 0 | K6: 1
A7: 15 Jun | B7: 37339 | C7: 1 | D7: 90.56 | E7: 4831 | F7: 6118 | G7: =IF(F7=0,0,E7/F7*100) | H7: 0 | I7: 0 | J7: 0 | K7: 4
A8: 15 Jun | B8: 39236 | C8: 1 | D8: 93.91 | E8: 5508 | F8: 5967 | G8: =IF(F8=0,0,E8/F8*100) | H8: 0 | I8: 0 | J8: 0 | K8: 1
A9: 15 Jun | B9: 37577 | C9: 1 | D9: 93.86 | E9: 4797 | F9: 5858 | G9: =IF(F9=0,0,E9/F9*100) | H9: 4 | I9: 4 | J9: 0 | K9: 6
A10: 15 Jun | B10: 39131 | C10: 1 | D10: 93.89 | E10: 4697 | F10: 5772 | G10: =IF(F10=0,0,E10/F10*100) | H10: 0 | I10: 0 | J10: 0 | K10: 3
A11: 15 Jun | B11: 37884 | C11: 1 | D11: 93.89 | E11: 4767 | F11: 5507 | G11: =IF(F11=0,0,E11/F11*100) | H11: 0 | I11: 0 | J11: 0 | K11: 2
A12: 15 Jun | B12: 37277 | C12: 1 | D12: 93.88 | E12: 4585 | F12: 5377 | G12: =IF(F12=0,0,E12/F12*100) | H12: 0 | I12: 0 | J12: 0 | K12: 2
A13: 15 Jun | B13: 37566 | C13: 1 | D13: 93.87 | E13: 4229 | F13: 4931 | G13: =IF(F13=0,0,E13/F13*100) | H13: 0 | I13: 0 | J13: 0 | K13: 3
A14: 15 Jun | B14: 37453 | C14: 1 | D14: 93.91 | E14: 4002 | F14: 4834 | G14: =IF(F14=0,0,E14/F14*100) | H14: 0 | I14: 0 | J14: 0 | K14: 3
A15: 15 Jun | B15: 30823 | C15: 1 | D15: 93.89 | E15: 4125 | F15: 4692 | G15: =IF(F15=0,0,E15/F15*100) | H15: 0 | I15: 0 | J15: 0 | K15: 2
... A37: 15 Jun | B37: 51347 | C37: 0 | D37: 1.08 | E37: 46 | F37: 50 | G37: =IF(F37=0,0,E37/F37*100) | H37: 0 | I37: 0 | J37: 0 | K37: 1
A38: 15 Jun | B38: Day Total | C38: =SUM(C4:C37) | D38: =SUM(D4:D37) | E38: =SUM(E4:E37) | F38: =SUMIF(E4:E37,">0",F4:F37) | G38: =IF(F38=0,0,E38/F38*100) | H38: =SUM(H4:H37) | I38: =SUM(I4:I37) | J38: =SUM(J4:J37) | K38: =SUM(K4:K37)
A39: 16 Jun | B39: 39236 | C39: 2 | D39: 93.91 | E39: 9026 | F39: 14624 | G39: =IF(F39=0,0,E39/F39*100) | H39: 0 | I39: 0 | J39: 0 | K39: 5
A40: 16 Jun | B40: 37507 | C40: 2 | D40: 93.91 | E40: 10066 | F40: 11576 | G40: =IF(F40=0,0,E40/F40*100) | H40: 0 | I40: 0 | J40: 0 | K40: 5
A41: 16 Jun | B41: 39047 | C41: 2 | D41: 93.9 | E41: 8395 | F41: 10010 | G41: =IF(F41=0,0,E41/F41*100) | H41: 0 | I41: 0 | J41: 0 | K41: 4
A42: 16 Jun | B42: 39235 | C42: 2 | D42: 93.06 | E42: 7314 | F42: 9428 | G42: =IF(F42=0,0,E42/F42*100) | H42: 0 | I42: 0 | J42: 0 | K42: 5
A43: 16 Jun | B43: 30791 | C43: 2 | D43: 93.89 | E43: 7882 | F43: 8954 | G43: =IF(F43=0,0,E43/F43*100) | H43: 0 | I43: 0 | J43: 0 | K43: 5
A44: 16 Jun | B44: 39028 | C44: 1 | D44: 93.89 | E44: 5288 | F44: 6175 | G44: =IF(F44=0,0,E44/F44*100) | H44: 0 | I44: 0 | J44: 0 | K44: 3
A45: 16 Jun | B45: 42010 | C45: 1 | D45: 93.86 | E45: 5066 | F45: 6095 | G45: =IF(F45=0,0,E45/F45*100) | H45: 1 | I45: 1 | J45: 0 | K45: 4
A46: 16 Jun | B46: 37396 | C46: 1 | D46: 93.89 | E46: 4948 | F46: 5804 | G46: =IF(F46=0,0,E46/F46*100) | H46: 0 | I46: 0 | J46: 0 | K46: 3
A47: 16 Jun | B47: 37050 | C47: 1 | D47: 93.32 | E47: 5534 | F47: 5658 | G47: =IF(F47=0,0,E47/F47*100) | H47: 0 | I47: 0 | J47: 0 | K47: 1
A48: 16 Jun | B48: 30480 | C48: 1 | D48: 93.89 | E48: 4793 | F48: 5612 | G48: =IF(F48=0,0,E48/F48*100) | H48: 0 | I48: 0 | J48: 0 | K48: 3
A49: 16 Jun | B49: 39514 | C49: 1 | D49: 93.89 | E49: 4273 | F49: 5155 | G49: =IF(F49=0,0,E49/F49*100) | H49: 0 | I49: 0 | J49: 0 | K49: 3
A50: 16 Jun | B50: 37684 | C50: 1 | D50: 93.89 | E50: 3852 | F50: 5136 | G50: =IF(F50=0,0,E50/F50*100) | H50: 0 | I50: 0 | J50: 0 | K50: 3
... A73: 16 Jun | B73: 30083 | C73: 0 | D73: 5.55 | E73: 0 | F73: 8 | G73: =IF(F73=0,0,E73/F73*100) | H73: 0 | I73: 0 | J73: 0 | K73: 0
A74: 16 Jun | B74: Day Total | C74: =SUM(C39:C73) | D74: =SUM(D39:D73) | E74: =SUM(E39:E73) | F74: =SUMIF(E39:E73,">0",F39:F73) | G74: =IF(F74=0,0,E74/F74*100) | H74: =SUM(H39:H73) | I74: =SUM(I39:I73) | J74: =SUM(J39:J73) | K74: =SUM(K39:K73)
A75: 17 Jun | B75: 37818 | C75: 2 | D75: 93.32 | E75: 11441 | F75: 11840 | G75: =IF(F75=0,0,E75/F75*100) | H75: 0 | I75: 0 | J75: 0 | K75: 4
A76: 17 Jun | B76: 30473 | C76: 2 | D76: 93.88 | E76: 9506 | F76: 11106 | G76: =IF(F76=0,0,E76/F76*100) | H76: 0 | I76: 0 | J76: 0 | K76: 5
A77: 17 Jun | B77: 37277 | C77: 2 | D77: 93.9 | E77: 8820 | F77: 10219 | G77: =IF(F77=0,0,E77/F77*100) | H77: 0 | I77: 0 | J77: 0 | K77: 5
A78: 17 Jun | B78: 37337 | C78: 2 | D78: 93.88 | E78: 7599 | F78: 8820 | G78: =IF(F78=0,0,E78/F78*100) | H78: 0 | I78: 0 | J78: 0 | K78: 7
A79: 17 Jun | B79: 37350 | C79: 2 | D79: 93.9 | E79: 7479 | F79: 8682 | G79: =IF(F79=0,0,E79/F79*100) | H79: 0 | I79: 0 | J79: 0 | K79: 8
A80: 17 Jun | B80: 37087 | C80: 1 | D80: 93.9 | E80: 6693 | F80: 8062 | G80: =IF(F80=0,0,E80/F80*100) | H80: 0 | I80: 0 | J80: 0 | K80: 3
A81: 17 Jun | B81: 37086 | C81: 1 | D81: 93.31 | E81: 7510 | F81: 8016 | G81: =IF(F81=0,0,E81/F81*100) | H81: 0 | I81: 0 | J81: 0 | K81: 2
A82: 17 Jun | B82: 39260 | C82: 1 | D82: 93.91 | E82: 5168 | F82: 7027 | G82: =IF(F82=0,0,E82/F82*100) | H82: 0 | I82: 0 | J82: 0 | K82: 3
A83: 17 Jun | B83: 37884 | C83: 1 | D83: 93.91 | E83: 5317 | F83: 6425 | G83: =IF(F83=0,0,E83/F83*100) | H83: 0 | I83: 0 | J83: 0 | K83: 3
...

Sheet EB Detail
A1: EB Detail — every Emergency-Brake event, with speed / MA / Emergency diagnostics + undesirable classification
A3: Total EB = 20 · Valid trips = 13 · Non-valid trips = 7 · Undesirable = 19
A5: Date | B5: Loco ID | C5: Trip Type | D5: Onset | E5: End | F5: Duration (s) | G5: EB Packets | H5: Max Speed | I5: Mode @onset | J5: Location (km) | K5: Dir | L5: Station | M5: Speed at EB (PG check) | N5: MA wrt Sig | O5: Emergency (LReg) | P5: Suspected Reason (undesirable)
A6: 15 Jun | B6: 37577 | C6: Valid | D6: 04:30:56 | E6: 04:32:30 | F6: 94 | G6: 48 | H6: 107 | I6: TRIP | J6: 470.41 | K6: N | L6: LC-294 | M6: 107 km/h | N6: n/a | O6: - | P6: Trip mode
A7: 15 Jun | B7: 37577 | C7: Valid | D7: 04:34:46 | E7: 04:34:48 | F7: 2 | G7: 2 | H7: 0 | I7: POSTTRIP | J7: 471.1 | K7: N | L7: LC-294 | M7: 0 km/h | N7: 0 | O7: - | P7: EB at 0-1 km/h
A8: 15 Jun | B8: 37577 | C8: Valid | D8: 04:36:32 | E8: 04:36:32 | F8: 0 | G8: 1 | H8: 0 | I8: POSTTRIP | J8: 471.1 | K8: N | L8: LC-294 | M8: 0 km/h | N8: 0 | O8: - | P8: EB at 0-1 km/h
A9: 15 Jun | B9: 37577 | C9: Valid | D9: 04:36:36 | E9: 04:36:36 | F9: 0 | G9: 1 | H9: 0 | I9: POSTTRIP | J9: 471.1 | K9: N | L9: LC-294 | M9: 0 km/h | N9: 0 | O9: - | P9: EB at 0-1 km/h
A10: 16 Jun | B10: 42010 | C10: Valid | D10: 09:20:34 | E10: 09:20:52 | F10: 18 | G10: 10 | H10: 54 | I10: SR | J10: 458.48 | K10: U | L10: GOTHAJ | M10: 54 km/h | N10: 5820 | O10: - | P10: FS->SR degradation + EB
A11: 16 Jun | B11: 37277 | C11: Valid | D11: 20:02:54 | E11: 20:03:56 | F11: 62 | G11: 32 | H11: 10 | I11: Failure | J11: 494.31 | K11: R | L11: AHMEDABAD Jn | M11: 10 km/h | N11: 2524 | O11: - | P11: Failure mode
A12: 17 Jun | B12: 39287 | C12: Non-Valid | D12: 01:39:32 | E12: 01:40:12 | F12: 40 | G12: 21 | H12: 0 | I12: TRIP | J12: 433.7 | K12: R | L12: ANAND Jn | M12: 0 km/h | N12: 0 | O12: - | P12: EB at 0-1 km/h; Trip mode
A13: 17 Jun | B13: 39287 | C13: Non-Valid | D13: 01:41:32 | E13: 01:41:32 | F13: 0 | G13: 1 | H13: 0 | I13: POSTTRIP | J13: 433.7 | K13: R | L13: ANAND Jn | M13: 0 km/h | N13: 0 | O13: - | P13: EB at 0-1 km/h
A14: 17 Jun | B14: 30829 | C14: Non-Valid | D14: 03:54:24 | E14: 03:56:14 | F14: 110 | G14: 47 | H14: 86 | I14: TRIP | J14: 447.98 | K14: R | L14: NADIAD | M14: 86 km/h | N14: 0 MA dropped from 1051 to 0. | O14: - | P14: Sudden MA drop; Emergency: SOS; Trip mode
A15: 18 Jun | B15: 37934 | C15: Valid | D15: 21:02:40 | E15: 21:02:56 | F15: 16 | G15: 9 | H15: 8 | I15: TRIP | J15: 494.54 | K15: N | L15: AHMEDABAD Jn | M15: 8 km/h | N15: 0 MA dropped from 1075 to 0. | O15: - | P15: Sudden MA drop; Trip mode
A16: 18 Jun | B16: 30460 | C16: Valid | D16: 22:23:38 | E16: 22:23:58 | F16: 20 | G16: 10 | H16: 55 | I16: TRIP | J16: 401.31 | K16: R | L16: BAJWA | M16: 55 km/h | N16: 1153 | O16: - | P16: Trip mode
A17: 19 Jun | B17: 37670 | C17: Valid | D17: 12:38:48 | E17: 12:38:58 | F17: 10 | G17: 6 | H17: 28 | I17: SR | J17: 407.89 | K17: U | L17: RANOLI | M17: 28 km/h | N17: 5395 | O17: - | P17: FS->SR degradation + EB
... A25: 20 Jun | B25: 37248 | C25: Valid | D25: 18:54:54 | E25: 18:54:58 | F25: 4 | G25: 3 | H25: 55 | I25: FS | J25: 488.72 | K25: R | L25: VATVA | M25: 55 km/h | N25: 1637 | O25: - | P25: -

Sheet KM Verification
A1: KM Verification - KM = (In-section Max Abs - In-section Min Abs) / 1000
A2: Section window: abs 400398 - 494312 (24000_ADI to 24051_BRC). Only positions inside this window count; 8388607 'unknown' is excluded. 'In Report'=No means no in-section travel (dropped).
A4: Date | B4: Loco ID | C4: Total pkts | D4: Valid-abs pkts | E4: In-section pkts | F4: Raw Min Abs | G4: Raw Max Abs | H4: In-sec Min Abs | I4: In-sec Max Abs | J4: KM = (Max-Min)/1000 | K4: In Report? | L4: Stations Passed (of 23) | M4: Stations Not Passed (if < full trip)
A5: 15 Jun | B5: 30791 | C5: 6816 | D5: 6816 | E5: 5691 | F5: 370107 | G5: 494969 | H5: 400402 | I5: 494310 | J5: =(I5-H5)/1000 | K5: Yes | L5: 23 | M5: - (full trip)
A6: 15 Jun | B6: 37453 | C6: 4834 | D6: 4834 | E6: 3795 | F6: 369889 | G6: 494980 | H6: 400406 | I6: 494312 | J6: =(I6-H6)/1000 | K6: Yes | L6: 23 | M6: - (full trip)
A7: 15 Jun | B7: 39236 | C7: 5967 | D7: 5967 | E7: 5418 | F7: 398295 | G7: 495787 | H7: 400403 | I7: 494312 | J7: =(I7-H7)/1000 | K7: Yes | L7: 23 | M7: - (full trip)
A8: 15 Jun | B8: 30472 | C8: 4422 | D8: 4422 | E8: 3635 | F8: 381183 | G8: 494931 | H8: 400409 | I8: 494312 | J8: =(I8-H8)/1000 | K8: Yes | L8: 23 | M8: - (full trip)
A9: 15 Jun | B9: 37830 | C9: 3725 | D9: 3725 | E9: 3267 | F9: 395500 | G9: 494976 | H9: 400408 | I9: 494312 | J9: =(I9-H9)/1000 | K9: Yes | L9: 23 | M9: - (full trip)
A10: 15 Jun | B10: 30330 | C10: 4044 | D10: 4029 | E10: 3306 | F10: 375137 | G10: 495017 | H10: 400420 | I10: 494312 | J10: =(I10-H10)/1000 | K10: Yes | L10: 23 | M10: - (full trip)
A11: 15 Jun | B11: 30823 | C11: 4692 | D11: 4692 | E11: 3627 | F11: 363219 | G11: 495780 | H11: 400421 | I11: 494309 | J11: =(I11-H11)/1000 | K11: Yes | L11: 23 | M11: - (full trip)
A12: 15 Jun | B12: 37884 | C12: 5507 | D12: 5507 | E12: 4477 | F12: 370020 | G12: 495808 | H12: 400424 | I12: 494312 | J12: =(I12-H12)/1000 | K12: Yes | L12: 23 | M12: - (full trip)
A13: 15 Jun | B13: 39131 | C13: 5772 | D13: 5772 | E13: 4227 | F13: 368159 | G13: 495811 | H13: 400425 | I13: 494312 | J13: =(I13-H13)/1000 | K13: Yes | L13: 23 | M13: - (full trip)
A14: 15 Jun | B14: 37277 | C14: 5377 | D14: 5377 | E14: 4215 | F14: 370509 | G14: 495804 | H14: 400435 | I14: 494311 | J14: =(I14-H14)/1000 | K14: Yes | L14: 23 | M14: - (full trip)
A15: 15 Jun | B15: 37566 | C15: 4931 | D15: 4931 | E15: 3937 | F15: 360712 | G15: 495784 | H15: 400436 | I15: 494308 | J15: =(I15-H15)/1000 | K15: Yes | L15: 23 | M15: - (full trip)
A16: 15 Jun | B16: 37577 | C16: 5858 | D16: 5858 | E16: 4607 | F16: 369513 | G16: 495805 | H16: 400443 | I16: 494308 | J16: =(I16-H16)/1000 | K16: Yes | L16: 23 | M16: - (full trip)
... A38: 15 Jun | B38: 39235 | C38: 471 | D38: 471 | E38: 220 | F38: 493488 | G38: 495008 | H38: 493488 | I38: 494312 | J38: =(I38-H38)/1000 | K38: Yes | L38: 2 | M38: BAJWA, RANOLI, LC-246, VASAD, ADAS ROAD, VADOD, LC-258, ANAND Jn, LC-264, KANJARI BORIYAVI, UTARSANDA, NADIAD, LC-278, GOTHAJ, LC-286, MAHEMDABAD AND KHEDA ROAD, LC-294, KANIJ, BAREJADI NANDEJ, GERATPUR, VATVA
A39: 15 Jun | B39: 120850 | C39: 1087 | D39: 1049 | E39: 0 | F39: 510423 | G39: 515339 | H39: - | I39: - | J39: 0 | K39: No | L39: 0 | M39: BAJWA, RANOLI, LC-246, VASAD, ADAS ROAD, VADOD, LC-258, ANAND Jn, LC-264, KANJARI BORIYAVI, UTARSANDA, NADIAD, LC-278, GOTHAJ, LC-286, MAHEMDABAD AND KHEDA ROAD, LC-294, KANIJ, BAREJADI NANDEJ, GERATPUR, VATVA, KANKARIYA CABIN, AHMEDABAD Jn
A40: 15 Jun | B40: 33715 | C40: 5 | D40: 0 | E40: 0 | F40: - | G40: - | H40: - | I40: - | J40: 0 | K40: No | L40: 0 | M40: BAJWA, RANOLI, LC-246, VASAD, ADAS ROAD, VADOD, LC-258, ANAND Jn, LC-264, KANJARI BORIYAVI, UTARSANDA, NADIAD, LC-278, GOTHAJ, LC-286, MAHEMDABAD AND KHEDA ROAD, LC-294, KANIJ, BAREJADI NANDEJ, GERATPUR, VATVA, KANKARIYA CABIN, AHMEDABAD Jn
A41: 15 Jun | B41: 37087 | C41: 6 | D41: 0 | E41: 0 | F41: - | G41: - | H41: - | I41: - | J41: 0 | K41: No | L41: 0 | M41: BAJWA, RANOLI, LC-246, VASAD, ADAS ROAD, VADOD, LC-258, ANAND Jn, LC-264, KANJARI BORIYAVI, UTARSANDA, NADIAD, LC-278, GOTHAJ, LC-286, MAHEMDABAD AND KHEDA ROAD, LC-294, KANIJ, BAREJADI NANDEJ, GERATPUR, VATVA, KANKARIYA CABIN, AHMEDABAD Jn
A42: 15 Jun | B42: 37491 | C42: 18 | D42: 0 | E42: 0 | F42: - | G42: - | H42: - | I42: - | J42: 0 | K42: No | L42: 0 | M42: BAJWA, RANOLI, LC-246, VASAD, ADAS ROAD, VADOD, LC-258, ANAND Jn, LC-264, KANJARI BORIYAVI, UTARSANDA, NADIAD, LC-278, GOTHAJ, LC-286, MAHEMDABAD AND KHEDA ROAD, LC-294, KANIJ, BAREJADI NANDEJ, GERATPUR, VATVA, KANKARIYA CABIN, AHMEDABAD Jn
A43: 15 Jun | B43: 37855 | C43: 24 | D43: 0 | E43: 0 | F43: - | G43: - | H43: - | I43: - | J43: 0 | K43: No | L43: 0 | M43: BAJWA, RANOLI, LC-246, VASAD, ADAS ROAD, VADOD, LC-258, ANAND Jn, LC-264, KANJARI BORIYAVI, UTARSANDA, NADIAD, LC-278, GOTHAJ, LC-286, MAHEMDABAD AND KHEDA ROAD, LC-294, KANIJ, BAREJADI NANDEJ, GERATPUR, VATVA, KANKARIYA CABIN, AHMEDABAD Jn
A44: 15 Jun | B44: 39254 | C44: 19 | D44: 0 | E44: 0 | F44: - | G44: - | H44: - | I44: - | J44: 0 | K44: No | L44: 0 | M44: BAJWA, RANOLI, LC-246, VASAD, ADAS ROAD, VADOD, LC-258, ANAND Jn, LC-264, KANJARI BORIYAVI, UTARSANDA, NADIAD, LC-278, GOTHAJ, LC-286, MAHEMDABAD AND KHEDA ROAD, LC-294, KANIJ, BAREJADI NANDEJ, GERATPUR, VATVA, KANKARIYA CABIN, AHMEDABAD Jn
A45: 15 Jun | B45: 39258 | C45: 17 | D45: 0 | E45: 0 | F45: - | G45: - | H45: - | I45: - | J45: 0 | K45: No | L45: 0 | M45: BAJWA, RANOLI, LC-246, VASAD, ADAS ROAD, VADOD, LC-258, ANAND Jn, LC-264, KANJARI BORIYAVI, UTARSANDA, NADIAD, LC-278, GOTHAJ, LC-286, MAHEMDABAD AND KHEDA ROAD, LC-294, KANIJ, BAREJADI NANDEJ, GERATPUR, VATVA, KANKARIYA CABIN, AHMEDABAD Jn
A46: 15 Jun | B46: 39287 | C46: 462 | D46: 462 | E46: 0 | F46: 360560 | G46: 395920 | H46: - | I46: - | J46: 0 | K46: No | L46: 0 | M46: BAJWA, RANOLI, LC-246, VASAD, ADAS ROAD, VADOD, LC-258, ANAND Jn, LC-264, KANJARI BORIYAVI, UTARSANDA, NADIAD, LC-278, GOTHAJ, LC-286, MAHEMDABAD AND KHEDA ROAD, LC-294, KANIJ, BAREJADI NANDEJ, GERATPUR, VATVA, KANKARIYA CABIN, AHMEDABAD Jn
A47: 15 Jun | B47: 41430 | C47: 225 | D47: 205 | E47: 0 | F47: 2500003 | G47: 2500595 | H47: - | I47: - | J47: 0 | K47: No | L47: 0 | M47: BAJWA, RANOLI, LC-246, VASAD, ADAS ROAD, VADOD, LC-258, ANAND Jn, LC-264, KANJARI BORIYAVI, UTARSANDA, NADIAD, LC-278, GOTHAJ, LC-286, MAHEMDABAD AND KHEDA ROAD, LC-294, KANIJ, BAREJADI NANDEJ, GERATPUR, VATVA, KANKARIYA CABIN, AHMEDABAD Jn
A48: 16 Jun | B48: 30470 | C48: 4794 | D48: 4794 | E48: 4009 | F48: 375037 | G48: 494965 | H48: 400399 | I48: 494312 | J48: =(I48-H48)/1000 | K48: Yes | L48: 23 | M48: - (full trip)
A49: 16 Jun | B49: 37507 | C49: 11576 | D49: 11576 | E49: 9730 | F49: 370443 | G49: 495784 | H49: 400403 | I49: 494310 | J49: =(I49-H49)/1000 | K49: Yes | L49: 23 | M49: - (full trip)
A50: 16 Jun | B50: 39236 | C50: 14624 | D50: 11059 | E50: 9179 | F50: 398188 | G50: 495771 | H50: 400399 | I50: 494311 | J50: =(I50-H50)/1000 | K50: Yes | L50: 23 | M50: - (full trip)
A51: 16 Jun | B51: 30821 | C51: 4714 | D51: 4714 | E51: 3668 | F51: 370255 | G51: 494966 | H51: 400410 | I51: 494312 | J51: =(I51-H51)/1000 | K51: Yes | L51: 23 | M51: - (full trip)
A52: 16 Jun | B52: 39047 | C52: 10010 | D52: 9985 | E52: 8085 | F52: 370073 | G52: 495698 | H52: 400412 | I52: 494312 | J52: =(I52-H52)/1000 | K52: Yes | L52: 23 | M52: - (full trip)
A53: 16 Jun | B53: 39287 | C53: 5022 | D53: 5022 | E53: 4271 | F53: 360724 | G53: 495466 | H53: 400406 | I53: 494310 | J53: =(I53-H53)/1000 | K53: Yes | L53: 23 | M53: - (full trip)
A54: 16 Jun | B54: 30480 | C54: 5612 | D54: 5612 | E54: 4660 | F54: 370366 | G54: 494968 | H54: 400419 | I54: 494312 | J54: =(I54-H54)/1000 | K54: Yes | L54: 23 | M54: - (full trip)
A55: 16 Jun | B55: 30791 | C55: 8954 | D55: 8948 | E55: 7591 | F55: 375235 | G55: 495786 | H55: 400425 | I55: 494311 | J55: =(I55-H55)/1000 | K55: Yes | L55: 23 | M55: - (full trip)
A56: 16 Jun | B56: 37350 | C56: 5045 | D56: 5045 | E56: 3900 | F56: 374397 | G56: 495722 | H56: 400416 | I56: 494308 | J56: =(I56-H56)/1000 | K56: Yes | L56: 23 | M56: - (full trip)
A57: 16 Jun | B57: 37396 | C57: 5804 | D57: 5801 | E57: 4846 | F57: 370277 | G57: 495780 | H57: 400417 | I57: 494302 | J57: =(I57-H57)/1000 | K57: Yes | L57: 23 | M57: - (full trip)
A58: 16 Jun | B58: 37684 | C58: 5136 | D58: 5136 | E58: 3589 | F58: 371393 | G58: 494980 | H58: 400415 | I58: 494310 | J58: =(I58-H58)/1000 | K58: Yes | L58: 23 | M58: - (full trip)
A59: 16 Jun | B59: 39028 | C59: 6175 | D59: 6175 | E59: 5049 | F59: 370210 | G59: 494981 | H59: 400419 | I59: 494312 | J59: =(I59-H59)/1000 | K59: Yes | L59: 23 | M59: - (full trip)
... A82: 16 Jun | B82: 37746 | C82: 1095 | D82: 1068 | E82: 281 | F82: 380713 | G82: 402392 | H82: 400412 | I82: 402392 | J82: =(I82-H82)/1000 | K82: Yes | L82: 1 | M82: RANOLI, LC-246, VASAD, ADAS ROAD, VADOD, LC-258, ANAND Jn, LC-264, KANJARI BORIYAVI, UTARSANDA, NADIAD, LC-278, GOTHAJ, LC-286, MAHEMDABAD AND KHEDA ROAD, LC-294, KANIJ, BAREJADI NANDEJ, GERATPUR, VATVA, KANKARIYA CABIN, AHMEDABAD Jn
A83: 16 Jun | B83: 120850 | C83: 3237 | D83: 3170 | E83: 0 | F83: 510425 | G83: 520095 | H83: - | I83: - | J83: 0 | K83: No | L83: 0 | M83: BAJWA, RANOLI, LC-246, VASAD, ADAS ROAD, VADOD, LC-258, ANAND Jn, LC-264, KANJARI BORIYAVI, UTARSANDA, NADIAD, LC-278, GOTHAJ, LC-286, MAHEMDABAD AND KHEDA ROAD, LC-294, KANIJ, BAREJADI NANDEJ, GERATPUR, VATVA, KANKARIYA CABIN, AHMEDABAD Jn
A84: 16 Jun | B84: 30062 | C84: 9 | D84: 0 | E84: 0 | F84: - | G84: - | H84: - | I84: - | J84: 0 | K84: No | L84: 0 | M84: BAJWA, RANOLI, LC-246, VASAD, ADAS ROAD, VADOD, LC-258, ANAND Jn, LC-264, KANJARI BORIYAVI, UTARSANDA, NADIAD, LC-278, GOTHAJ, LC-286, MAHEMDABAD AND KHEDA ROAD, LC-294, KANIJ, BAREJADI NANDEJ, GERATPUR, VATVA, KANKARIYA CABIN, AHMEDABAD Jn
...

Sheet Methodology
B1: Methodology
B3: Excluded | C3: Loco-days with 0 km in the section (abs never inside the section, i.e. no section travel) are dropped from the report, unless they completed a trip.
B4: No of Trips | C4: A direction-run covering within 5 km of its line length (DN 93.91 / UP 93.91 km) = one FULL trip; out-and-back = 2. A loco with >=1 full trip is 'valid' (its EBs count as Valid). KM Verification lists each loco-day's stations passed / not passed.
B5: Total KMs Run on Kavach | C5: Section coverage per loco = how far it travelled across the section = (max - min) of its abs within the section limits (400398-494312). Capped at the section length; 0 if the loco never reported inside the section.
B6: Availability (FS+OS) | C6: Packets in FS or OnSight ÷ all packets (all modes) × 100.
B7: Total EB | C7: EB events in LReg brake status; one continuous hold = 1 (lost-packet gaps bridged, new event only at a real release). Split into Valid (trip locos) / Non-Valid.
B8: Mode Degradation | C8: FS→Trip/LS/SR/Standby & OS→SR/Standby (every transition). Excluded: start-of-mission/re-init SR, NonLeading→SR, FS→SR at 0 km/h, boundary-station re-init (917-reverse).
B9: EB diagnostics | C9: Speed at EB + flag a PG issue only if it jumps >=6 km/h vs the IMMEDIATELY preceding packet AND that packet is within 2 s of the EB (if the previous packet was lost, no PG flag); MA from SReg 'MA wrt Sig' + flag drop >500; Emergency from LReg.
B10: Ratios | C10: per Trip=÷Trips; per KM=÷KM; per 100 KM=÷KM×100; per Trip per 1000 KM=÷(Trips×KM/1000); per Trip per 100 KM=÷(Trips×KM/100).
