Workbook

Sheet Unified KPI
A1: WR — Kavach Unified KPI
A2: Period: 21 Jun - 27 Jun 2026 · all locomotives · one combined row
A4: Month | B4: Zone | C4: Section | D4: No Of Trips | E4: Total KMs Run On Kavach | F4: Availability (FS+OS) | G4: Total EB | H4: EB (Valid Trips) | I4: EB (Non-Valid Trips) | J4: EB per Trip | K4: EB per KM | L4: EB per 100 KM | M4: EB per Trip per 1000 KM | N4: Total Mode Degradation | O4: Mode Degradation per Trip | P4: Mode Degradation per KM | Q4: Mode Degradation per Trip per 100 KM | R4: Mode Degradation per 100 KM | S4: Undesirable EB | T4: UNIFIED KPI
A5: 21 Jun - 27 Jun 2026 | B5: WR | C5: 24000_ADI - 24223 (WR03, BRC excluded) | D5: ='Daily Breakdown'!C302 | E5: ='Daily Breakdown'!D302 | F5: ='Daily Breakdown'!G302 | G5: ='Daily Breakdown'!H302 | H5: ='Daily Breakdown'!I302 | I5: ='Daily Breakdown'!J302 | J5: =IFERROR(G5/D5,0) | K5: =IFERROR(G5/E5,0) | L5: =IFERROR(G5/E5*100,0) | M5: =IFERROR(G5/(D5*E5/1000),0) | N5: ='Daily Breakdown'!K302 | O5: =IFERROR(N5/D5,0) | P5: =IFERROR(N5/E5,0) | Q5: =IFERROR(N5/(D5*E5/100),0) | R5: =IFERROR(N5/E5*100,0) | S5: 19 | T5: =ROUND(F5*(1-M5)*(1-Q5),2)

Sheet Daily Breakdown
A1: Daily Breakdown — by day and locomotive (all locos)
A2: Availability base excludes locos with FS+OS pkts = 0 (they are still listed; only the Total-pkts availability base drops them).
A3: Date | B3: Loco ID | C3: No of Trips | D3: Total KMs | E3: FS+OS pkts | F3: Total pkts | G3: Availability (FS+OS) | H3: Total EB | I3: EB (Valid) | J3: EB (Non-Valid) | K3: Mode Degradation
A4: 21 Jun | B4: 37503 | C4: 2 | D4: 93.9 | E4: 8148 | F4: 9704 | G4: =IF(F4=0,0,E4/F4*100) | H4: 0 | I4: 0 | J4: 0 | K4: 7
A5: 21 Jun | B5: 37793 | C5: 1 | D5: 93.87 | E5: 8258 | F5: 9173 | G5: =IF(F5=0,0,E5/F5*100) | H5: 0 | I5: 0 | J5: 0 | K5: 8
A6: 21 Jun | B6: 37275 | C6: 1 | D6: 93.32 | E6: 7834 | F6: 8155 | G6: =IF(F6=0,0,E6/F6*100) | H6: 0 | I6: 0 | J6: 0 | K6: 8
A7: 21 Jun | B7: 37818 | C7: 1 | D7: 93.32 | E7: 7326 | F7: 7599 | G7: =IF(F7=0,0,E7/F7*100) | H7: 0 | I7: 0 | J7: 0 | K7: 5
A8: 21 Jun | B8: 39311 | C8: 1 | D8: 91.7 | E8: 6904 | F8: 7235 | G8: =IF(F8=0,0,E8/F8*100) | H8: 0 | I8: 0 | J8: 0 | K8: 3
A9: 21 Jun | B9: 39287 | C9: 1 | D9: 93.91 | E9: 6603 | F9: 7027 | G9: =IF(F9=0,0,E9/F9*100) | H9: 0 | I9: 0 | J9: 0 | K9: 6
A10: 21 Jun | B10: 30065 | C10: 1 | D10: 90.88 | E10: 6562 | F10: 6914 | G10: =IF(F10=0,0,E10/F10*100) | H10: 0 | I10: 0 | J10: 0 | K10: 2
A11: 21 Jun | B11: 30814 | C11: 1 | D11: 93.91 | E11: 5582 | F11: 6772 | G11: =IF(F11=0,0,E11/F11*100) | H11: 0 | I11: 0 | J11: 0 | K11: 3
A12: 21 Jun | B12: 30476 | C12: 1 | D12: 93.89 | E12: 4572 | F12: 6670 | G12: =IF(F12=0,0,E12/F12*100) | H12: 0 | I12: 0 | J12: 0 | K12: 5
A13: 21 Jun | B13: 33715 | C13: 1 | D13: 93.86 | E13: 5255 | F13: 5912 | G13: =IF(F13=0,0,E13/F13*100) | H13: 0 | I13: 0 | J13: 0 | K13: 2
A14: 21 Jun | B14: 30791 | C14: 1 | D14: 93.91 | E14: 4000 | F14: 5560 | G14: =IF(F14=0,0,E14/F14*100) | H14: 0 | I14: 0 | J14: 0 | K14: 4
A15: 21 Jun | B15: 37074 | C15: 1 | D15: 93.31 | E15: 5414 | F15: 5540 | G15: =IF(F15=0,0,E15/F15*100) | H15: 0 | I15: 0 | J15: 0 | K15: 1
... A46: 21 Jun | B46: 30176 | C46: 0 | D46: 59.67 | E46: 0 | F46: 28 | G46: =IF(F46=0,0,E46/F46*100) | H46: 0 | I46: 0 | J46: 0 | K46: 0
A47: 21 Jun | B47: Day Total | C47: =SUM(C4:C46) | D47: =SUM(D4:D46) | E47: =SUM(E4:E46) | F47: =SUMIF(E4:E46,">0",F4:F46) | G47: =IF(F47=0,0,E47/F47*100) | H47: =SUM(H4:H46) | I47: =SUM(I4:I46) | J47: =SUM(J4:J46) | K47: =SUM(K4:K46)
A48: 22 Jun | B48: 33715 | C48: 2 | D48: 93.91 | E48: 9893 | F48: 12469 | G48: =IF(F48=0,0,E48/F48*100) | H48: 0 | I48: 0 | J48: 0 | K48: 4
A49: 22 Jun | B49: 37287 | C49: 1 | D49: 93.9 | E49: 6006 | F49: 7013 | G49: =IF(F49=0,0,E49/F49*100) | H49: 1 | I49: 1 | J49: 0 | K49: 3
A50: 22 Jun | B50: 37793 | C50: 1 | D50: 93.91 | E50: 5176 | F50: 6748 | G50: =IF(F50=0,0,E50/F50*100) | H50: 0 | I50: 0 | J50: 0 | K50: 2
A51: 22 Jun | B51: 37337 | C51: 1 | D51: 93.9 | E51: 5136 | F51: 6420 | G51: =IF(F51=0,0,E51/F51*100) | H51: 0 | I51: 0 | J51: 0 | K51: 4
A52: 22 Jun | B52: 37887 | C52: 1 | D52: 93.91 | E52: 5506 | F52: 6274 | G52: =IF(F52=0,0,E52/F52*100) | H52: 0 | I52: 0 | J52: 0 | K52: 3
A53: 22 Jun | B53: 37163 | C53: 1 | D53: 93.91 | E53: 4315 | F53: 5917 | G53: =IF(F53=0,0,E53/F53*100) | H53: 0 | I53: 0 | J53: 0 | K53: 5
A54: 22 Jun | B54: 30507 | C54: 1 | D54: 93.91 | E54: 5495 | F54: 5846 | G54: =IF(F54=0,0,E54/F54*100) | H54: 0 | I54: 0 | J54: 0 | K54: 3
A55: 22 Jun | B55: 30476 | C55: 1 | D55: 93.91 | E55: 5236 | F55: 5790 | G55: =IF(F55=0,0,E55/F55*100) | H55: 0 | I55: 0 | J55: 0 | K55: 2
A56: 22 Jun | B56: 30167 | C56: 1 | D56: 93.89 | E56: 4658 | F56: 5218 | G56: =IF(F56=0,0,E56/F56*100) | H56: 0 | I56: 0 | J56: 0 | K56: 2
A57: 22 Jun | B57: 37453 | C57: 1 | D57: 93.9 | E57: 3995 | F57: 5204 | G57: =IF(F57=0,0,E57/F57*100) | H57: 0 | I57: 0 | J57: 0 | K57: 4
A58: 22 Jun | B58: 37020 | C58: 1 | D58: 93.88 | E58: 4374 | F58: 5055 | G58: =IF(F58=0,0,E58/F58*100) | H58: 0 | I58: 0 | J58: 0 | K58: 2
A59: 22 Jun | B59: 30770 | C59: 1 | D59: 93.87 | E59: 4128 | F59: 4784 | G59: =IF(F59=0,0,E59/F59*100) | H59: 0 | I59: 0 | J59: 0 | K59: 2
... A89: 22 Jun | B89: 39405 | C89: 0 | D89: 35.76 | E89: 0 | F89: 975 | G89: =IF(F89=0,0,E89/F89*100) | H89: 0 | I89: 0 | J89: 0 | K89: 0
A90: 22 Jun | B90: Day Total | C90: =SUM(C48:C89) | D90: =SUM(D48:D89) | E90: =SUM(E48:E89) | F90: =SUMIF(E48:E89,">0",F48:F89) | G90: =IF(F90=0,0,E90/F90*100) | H90: =SUM(H48:H89) | I90: =SUM(I48:I89) | J90: =SUM(J48:J89) | K90: =SUM(K48:K89)
A91: 23 Jun | B91: 30533 | C91: 2 | D91: 93.32 | E91: 12715 | F91: 13088 | G91: =IF(F91=0,0,E91/F91*100) | H91: 0 | I91: 0 | J91: 0 | K91: 6
A92: 23 Jun | B92: 37350 | C92: 2 | D92: 93.91 | E92: 8191 | F92: 10495 | G92: =IF(F92=0,0,E92/F92*100) | H92: 0 | I92: 0 | J92: 0 | K92: 6
A93: 23 Jun | B93: 37793 | C93: 2 | D93: 93.91 | E93: 7550 | F93: 8860 | G93: =IF(F93=0,0,E93/F93*100) | H93: 0 | I93: 0 | J93: 0 | K93: 4
A94: 23 Jun | B94: 39467 | C94: 1 | D94: 93.89 | E94: 7235 | F94: 9188 | G94: =IF(F94=0,0,E94/F94*100) | H94: 1 | I94: 1 | J94: 0 | K94: 4
A95: 23 Jun | B95: 30507 | C95: 1 | D95: 93.91 | E95: 7643 | F95: 8298 | G95: =IF(F95=0,0,E95/F95*100) | H95: 1 | I95: 1 | J95: 0 | K95: 5
A96: 23 Jun | B96: 37780 | C96: 1 | D96: 93.88 | E96: 7216 | F96: 7806 | G96: =IF(F96=0,0,E96/F96*100) | H96: 0 | I96: 0 | J96: 0 | K96: 6
A97: 23 Jun | B97: 37131 | C97: 1 | D97: 93.86 | E97: 6181 | F97: 6828 | G97: =IF(F97=0,0,E97/F97*100) | H97: 1 | I97: 1 | J97: 0 | K97: 2
A98: 23 Jun | B98: 39466 | C98: 1 | D98: 93.9 | E98: 4949 | F98: 6478 | G98: =IF(F98=0,0,E98/F98*100) | H98: 0 | I98: 0 | J98: 0 | K98: 3
A99: 23 Jun | B99: 37339 | C99: 1 | D99: 93.87 | E99: 5488 | F99: 6357 | G99: =IF(F99=0,0,E99/F99*100) | H99: 0 | I99: 0 | J99: 0 | K99: 2
...

Sheet EB Detail
A1: EB Detail — every Emergency-Brake event, with speed / MA / Emergency diagnostics + undesirable classification
A3: Total EB = 19 · Valid trips = 13 · Non-valid trips = 6 · Undesirable = 19
A5: Date | B5: Loco ID | C5: Trip Type | D5: Onset | E5: End | F5: Duration (s) | G5: EB Packets | H5: Max Speed | I5: Mode @onset | J5: Location (km) | K5: Dir | L5: Station | M5: Speed at EB (PG check) | N5: MA wrt Sig | O5: Emergency (LReg) | P5: Suspected Reason (undesirable) | Q5: Loco Type
A6: 22 Jun | B6: 37287 | C6: Valid | D6: 18:57:06 | E6: 18:57:08 | F6: 2 | G6: 2 | H6: 94 | I6: FS | J6: 421.08 | K6: N | L6: ADAS ROAD | M6: 94 km/h | N6: 393 MA dropped from 2780 to 393. | O6: - | P6: Sudden MA drop | Q6: Medha/Kernex
A7: 23 Jun | B7: 30507 | C7: Valid | D7: 11:37:36 | E7: 11:39:14 | F7: 98 | G7: 49 | H7: 3 | I7: TRIP | J7: 433.7 | K7: R | L7: ANAND Jn | M7: 3 km/h | N7: 0 | O7: - | P7: Trip mode | Q7: Medha/Kernex
A8: 23 Jun | B8: 39467 | C8: Valid | D8: 17:15:58 | E8: 17:16:00 | F8: 2 | G8: 2 | H8: 11 | I8: SR | J8: 403.47 | K8: U | L8: BAJWA | M8: 11 km/h | N8: 0 | O8: - | P8: FS->SR degradation + EB | Q8: HBL
A9: 23 Jun | B9: 37131 | C9: Valid | D9: 19:48:08 | E9: 19:48:08 | F9: 0 | G9: 1 | H9: 104 | I9: FS | J9: 420.7 | K9: N | L9: ADAS ROAD | M9: 104 km/h | N9: 1074 MA dropped from 3272 to 1074. | O9: - | P9: Sudden MA drop | Q9: Medha/Kernex
A10: 24 Jun | B10: 30829 | C10: Non-Valid | D10: 04:09:50 | E10: 04:10:26 | F10: 36 | G10: 19 | H10: 23 | I10: TRIP | J10: 432.62 | K10: R | L10: ANAND Jn | M10: 22 km/h | N10: 0 MA dropped from 4758 to 0. | O10: - | P10: Sudden MA drop; Trip mode | Q10: Medha/Kernex
A11: 24 Jun | B11: 30829 | C11: Non-Valid | D11: 04:10:32 | E11: 04:10:40 | F11: 8 | G11: 5 | H11: 0 | I11: TRIP | J11: 432.56 | K11: R | L11: ANAND Jn | M11: 0 km/h | N11: 1073 | O11: - | P11: EB at 0-1 km/h; Trip mode | Q11: Medha/Kernex
A12: 24 Jun | B12: 30829 | C12: Non-Valid | D12: 04:10:46 | E12: 04:11:20 | F12: 34 | G12: 17 | H12: 0 | I12: TRIP | J12: 432.56 | K12: R | L12: ANAND Jn | M12: 0 km/h | N12: 1073 | O12: - | P12: EB at 0-1 km/h; Trip mode | Q12: Medha/Kernex
A13: 24 Jun | B13: 39030 | C13: Valid | D13: 21:56:32 | E13: 21:56:46 | F13: 14 | G13: 8 | H13: 36 | I13: SR | J13: 497.73 | K13: U | L13: AHMEDABAD Jn | M13: 36 km/h | N13: 2785 | O13: - | P13: FS->SR degradation + EB | Q13: Medha/Kernex
A14: 26 Jun | B14: 37887 | C14: Valid | D14: 20:29:56 | E14: 20:30:02 | F14: 6 | G14: 4 | H14: 6 | I14: SR | J14: 495.57 | K14: U | L14: AHMEDABAD Jn | M14: 6 km/h | N14: 494 | O14: - | P14: FS->SR degradation + EB | Q14: Medha/Kernex
A15: 26 Jun | B15: 37020 | C15: Valid | D15: 23:04:08 | E15: 23:04:16 | F15: 8 | G15: 5 | H15: 40 | I15: FS | J15: 437.25 | K15: N | L15: KANJARI BORIYAVI | M15: 40 km/h | N15: 5593 | O15: RearEnd | P15: Emergency: RearEnd | Q15: Medha/Kernex
A16: 27 Jun | B16: 39096 | C16: Non-Valid | D16: 00:24:28 | E16: 00:24:38 | F16: 10 | G16: 4 | H16: 23 | I16: SR | J16: 493.19 | K16: U | L16: KANKARIYA CABIN | M16: 23 km/h | N16: 1222 | O16: - | P16: FS->SR degradation + EB | Q16: Medha/Kernex
A17: 27 Jun | B17: 30733 | C17: Valid | D17: 04:25:56 | E17: 04:26:20 | F17: 24 | G17: 13 | H17: 9 | I17: SR | J17: 494.75 | K17: U | L17: AHMEDABAD Jn | M17: 9 km/h | N17: 1046 | O17: - | P17: FS->SR degradation + EB | Q17: Medha/Kernex
... A24: 27 Jun | B24: 30581 | C24: Valid | D24: 16:41:48 | E24: 16:41:52 | F24: 4 | G24: 3 | H24: 1 | I24: POSTTRIP | J24: 402.53 | K24: R | L24: BAJWA | M24: 0 km/h | N24: 0 | O24: - | P24: EB at 0-1 km/h | Q24: Medha/Kernex

Sheet Mode Degradation
A1: Mode Degradation — one event = a transition into LS or SR from a less-degraded mode (FS, OS, Trip, PostTrip, Standby; plus LS→SR). NonLeading→LS/SR, FS→OS and any recovery to FS are not counted. Detected on the merged LReq+LReg timeline (LReq carries the LS/SR packets LReg drops); spells outside the section or with a >60s reporting gap (stabled / out of coverage) are excluded.
A3: Total Mode Degradation = 765 · one row = one transition into LS or SR
A5: Date | B5: Loco ID | C5: From | D5: To (degraded) | E5: Onset | F5: End | G5: Duration (s) | H5: Packets | I5: Location (km) | J5: Station | K5: Dir | L5: Valid Trip?
A6: 21 Jun | B6: 37086 | C6: FS | D6: SR | E6: 00:28:04 | F6: 00:29:12 | G6: 68 | H6: 39 | I6: 434.74 | J6: LC-264 | K6: R | L6: Non-Valid
A7: 21 Jun | B7: 30823 | C7: FS | D7: SR | E7: 00:35:28 | F7: 01:05:24 | G7: 1796 | H7: 720 | I7: 403.39 | J7: BAJWA | K7: R | L7: Non-Valid
A8: 21 Jun | B8: 37780 | C8: FS | D8: SR | E8: 00:39:14 | F8: 01:22:48 | G8: 2614 | H8: 1034 | I8: 402.51 | J8: BAJWA | K8: R | L8: Non-Valid
A9: 21 Jun | B9: 39258 | C9: FS | D9: SR | E9: 01:08:24 | F9: 01:08:24 | G9: 0 | H9: 1 | I9: 401.2 | J9: BAJWA | K9: R | L9: Non-Valid
A10: 21 Jun | B10: 37818 | C10: FS | D10: SR | E10: 01:55:46 | F10: 01:55:46 | G10: 0 | H10: 1 | I10: 402 | J10: BAJWA | K10: R | L10: Valid
A11: 21 Jun | B11: 37818 | C11: FS | D11: SR | E11: 01:55:48 | F11: 01:59:04 | G11: 196 | H11: 188 | I11: 401.99 | J11: BAJWA | K11: R | L11: Valid
A12: 21 Jun | B12: 37818 | C12: FS | D12: SR | E12: 02:34:32 | F12: 02:34:34 | G12: 2 | H12: 2 | I12: 431.97 | J12: ANAND Jn | K12: N | L12: Valid
A13: 21 Jun | B13: 30476 | C13: StandBy | D13: SR | E13: 02:56:22 | F13: 03:20:46 | G13: 1464 | H13: 734 | I13: 494.99 | J13: AHMEDABAD Jn | K13: U | L13: Valid
A14: 21 Jun | B14: 37818 | C14: FS | D14: LS | E14: 03:10:44 | F14: 03:11:34 | G14: 50 | H14: 27 | I14: 478.03 | J14: BAREJADI NANDEJ | K14: N | L14: Valid
A15: 21 Jun | B15: 37818 | C15: LS | D15: SR | E15: 03:11:36 | F15: 03:12:56 | G15: 80 | H15: 47 | I15: 479.71 | J15: BAREJADI NANDEJ | K15: N | L15: Valid
A16: 21 Jun | B16: 37684 | C16: FS | D16: SR | E16: 03:24:28 | F16: 04:06:56 | G16: 2548 | H16: 987 | I16: 403.19 | J16: BAJWA | K16: R | L16: Non-Valid
A17: 21 Jun | B17: 30460 | C17: FS | D17: SR | E17: 03:30:36 | F17: 04:14:24 | G17: 2628 | H17: 858 | I17: 402.35 | J17: BAJWA | K17: R | L17: Non-Valid
... A770: 27 Jun | B770: 37632 | C770: OS | D770: SR | E770: 23:58:44 | F770: 23:58:44 | G770: 0 | H770: 1 | I770: 435.46 | J770: LC-264 | K770: R | L770: Non-Valid

Sheet KM Verification
A1: KM Verification - KM = (In-section Max Abs - In-section Min Abs) / 1000
A2: Section window: abs 400398 - 494312 (24000_ADI - 24223 (WR03, BRC excluded)). Only positions inside this window count; 8388607 'unknown' is excluded. 'In Report'=No means no in-section travel (dropped).
A4: Date | B4: Loco ID | C4: Total pkts | D4: Valid-abs pkts | E4: In-section pkts | F4: Raw Min Abs | G4: Raw Max Abs | H4: In-sec Min Abs | I4: In-sec Max Abs | J4: KM = (Max-Min)/1000 | K4: In Report? | L4: Stations Passed (of 23) | M4: Stations Not Passed (if < full trip)
A5: 21 Jun | B5: 30791 | C5: 5560 | D5: 5560 | E5: 4072 | F5: 370180 | G5: 494966 | H5: 400398 | I5: 494310 | J5: =(I5-H5)/1000 | K5: Yes | L5: 23 | M5: - (full trip)
A6: 21 Jun | B6: 30814 | C6: 6772 | D6: 6772 | E6: 5128 | F6: 360651 | G6: 495793 | H6: 400405 | I6: 494312 | J6: =(I6-H6)/1000 | K6: Yes | L6: 23 | M6: - (full trip)
A7: 21 Jun | B7: 37569 | C7: 4647 | D7: 4647 | E7: 3977 | F7: 380745 | G7: 494966 | H7: 400398 | I7: 494310 | J7: =(I7-H7)/1000 | K7: Yes | L7: 23 | M7: - (full trip)
A8: 21 Jun | B8: 39030 | C8: 5253 | D8: 5253 | E8: 4048 | F8: 376785 | G8: 494981 | H8: 400403 | I8: 494312 | J8: =(I8-H8)/1000 | K8: Yes | L8: 23 | M8: - (full trip)
A9: 21 Jun | B9: 39248 | C9: 5176 | D9: 5176 | E9: 3918 | F9: 371166 | G9: 495009 | H9: 400401 | I9: 494311 | J9: =(I9-H9)/1000 | K9: Yes | L9: 23 | M9: - (full trip)
A10: 21 Jun | B10: 39287 | C10: 7027 | D10: 7009 | E10: 6243 | F10: 396003 | G10: 495605 | H10: 400401 | I10: 494310 | J10: =(I10-H10)/1000 | K10: Yes | L10: 23 | M10: - (full trip)
A11: 21 Jun | B11: 30531 | C11: 4828 | D11: 4828 | E11: 3983 | F11: 369958 | G11: 495777 | H11: 400415 | I11: 494311 | J11: =(I11-H11)/1000 | K11: Yes | L11: 23 | M11: - (full trip)
A12: 21 Jun | B12: 37279 | C12: 5487 | D12: 5487 | E12: 5015 | F12: 398303 | G12: 495779 | H12: 400402 | I12: 494305 | J12: =(I12-H12)/1000 | K12: Yes | L12: 23 | M12: - (full trip)
A13: 21 Jun | B13: 37503 | C13: 9704 | D13: 9704 | E13: 7647 | F13: 360727 | G13: 495806 | H13: 400415 | I13: 494312 | J13: =(I13-H13)/1000 | K13: Yes | L13: 23 | M13: - (full trip)
A14: 21 Jun | B14: 30476 | C14: 6670 | D14: 5896 | E14: 4496 | F14: 370027 | G14: 500172 | H14: 400416 | I14: 494311 | J14: =(I14-H14)/1000 | K14: Yes | L14: 23 | M14: - (full trip)
A15: 21 Jun | B15: 37287 | C15: 5100 | D15: 5100 | E15: 3693 | F15: 367864 | G15: 494963 | H15: 400422 | I15: 494310 | J15: =(I15-H15)/1000 | K15: Yes | L15: 23 | M15: - (full trip)
A16: 21 Jun | B16: 30314 | C16: 5362 | D16: 5362 | E16: 4457 | F16: 370259 | G16: 495731 | H16: 400433 | I16: 494310 | J16: =(I16-H16)/1000 | K16: Yes | L16: 23 | M16: - (full trip)
... A47: 21 Jun | B47: 39467 | C47: 815 | D47: 788 | E47: 431 | F47: 395422 | G47: 402392 | H47: 400399 | I47: 402392 | J47: =(I47-H47)/1000 | K47: Yes | L47: 1 | M47: RANOLI, LC-246, VASAD, ADAS ROAD, VADOD, LC-258, ANAND Jn, LC-264, KANJARI BORIYAVI, UTARSANDA, NADIAD, LC-278, GOTHAJ, LC-286, MAHEMDABAD AND KHEDA ROAD, LC-294, KANIJ, BAREJADI NANDEJ, GERATPUR, VATVA, KANKARIYA CABIN, AHMEDABAD Jn
A48: 21 Jun | B48: 30358 | C48: 6 | D48: 0 | E48: 0 | F48: - | G48: - | H48: - | I48: - | J48: 0 | K48: No | L48: 0 | M48: BAJWA, RANOLI, LC-246, VASAD, ADAS ROAD, VADOD, LC-258, ANAND Jn, LC-264, KANJARI BORIYAVI, UTARSANDA, NADIAD, LC-278, GOTHAJ, LC-286, MAHEMDABAD AND KHEDA ROAD, LC-294, KANIJ, BAREJADI NANDEJ, GERATPUR, VATVA, KANKARIYA CABIN, AHMEDABAD Jn
A49: 21 Jun | B49: 32649 | C49: 498 | D49: 416 | E49: 0 | F49: 2499972 | G49: 2500647 | H49: - | I49: - | J49: 0 | K49: No | L49: 0 | M49: BAJWA, RANOLI, LC-246, VASAD, ADAS ROAD, VADOD, LC-258, ANAND Jn, LC-264, KANJARI BORIYAVI, UTARSANDA, NADIAD, LC-278, GOTHAJ, LC-286, MAHEMDABAD AND KHEDA ROAD, LC-294, KANIJ, BAREJADI NANDEJ, GERATPUR, VATVA, KANKARIYA CABIN, AHMEDABAD Jn
A50: 21 Jun | B50: 37111 | C50: 298 | D50: 298 | E50: 0 | F50: 361572 | G50: 395917 | H50: - | I50: - | J50: 0 | K50: No | L50: 0 | M50: BAJWA, RANOLI, LC-246, VASAD, ADAS ROAD, VADOD, LC-258, ANAND Jn, LC-264, KANJARI BORIYAVI, UTARSANDA, NADIAD, LC-278, GOTHAJ, LC-286, MAHEMDABAD AND KHEDA ROAD, LC-294, KANIJ, BAREJADI NANDEJ, GERATPUR, VATVA, KANKARIYA CABIN, AHMEDABAD Jn
A51: 21 Jun | B51: 37350 | C51: 10 | D51: 10 | E51: 0 | F51: 379696 | G51: 382968 | H51: - | I51: - | J51: 0 | K51: No | L51: 0 | M51: BAJWA, RANOLI, LC-246, VASAD, ADAS ROAD, VADOD, LC-258, ANAND Jn, LC-264, KANJARI BORIYAVI, UTARSANDA, NADIAD, LC-278, GOTHAJ, LC-286, MAHEMDABAD AND KHEDA ROAD, LC-294, KANIJ, BAREJADI NANDEJ, GERATPUR, VATVA, KANKARIYA CABIN, AHMEDABAD Jn
A52: 21 Jun | B52: 37602 | C52: 405 | D52: 405 | E52: 0 | F52: 363410 | G52: 395922 | H52: - | I52: - | J52: 0 | K52: No | L52: 0 | M52: BAJWA, RANOLI, LC-246, VASAD, ADAS ROAD, VADOD, LC-258, ANAND Jn, LC-264, KANJARI BORIYAVI, UTARSANDA, NADIAD, LC-278, GOTHAJ, LC-286, MAHEMDABAD AND KHEDA ROAD, LC-294, KANIJ, BAREJADI NANDEJ, GERATPUR, VATVA, KANKARIYA CABIN, AHMEDABAD Jn
A53: 21 Jun | B53: 37781 | C53: 293 | D53: 293 | E53: 0 | F53: 369607 | G53: 394003 | H53: - | I53: - | J53: 0 | K53: No | L53: 0 | M53: BAJWA, RANOLI, LC-246, VASAD, ADAS ROAD, VADOD, LC-258, ANAND Jn, LC-264, KANJARI BORIYAVI, UTARSANDA, NADIAD, LC-278, GOTHAJ, LC-286, MAHEMDABAD AND KHEDA ROAD, LC-294, KANIJ, BAREJADI NANDEJ, GERATPUR, VATVA, KANKARIYA CABIN, AHMEDABAD Jn
A54: 21 Jun | B54: 39014 | C54: 883 | D54: 883 | E54: 0 | F54: 363508 | G54: 398110 | H54: - | I54: - | J54: 0 | K54: No | L54: 0 | M54: BAJWA, RANOLI, LC-246, VASAD, ADAS ROAD, VADOD, LC-258, ANAND Jn, LC-264, KANJARI BORIYAVI, UTARSANDA, NADIAD, LC-278, GOTHAJ, LC-286, MAHEMDABAD AND KHEDA ROAD, LC-294, KANIJ, BAREJADI NANDEJ, GERATPUR, VATVA, KANKARIYA CABIN, AHMEDABAD Jn
A55: 21 Jun | B55: 39089 | C55: 329 | D55: 329 | E55: 0 | F55: 374169 | G55: 395849 | H55: - | I55: - | J55: 0 | K55: No | L55: 0 | M55: BAJWA, RANOLI, LC-246, VASAD, ADAS ROAD, VADOD, LC-258, ANAND Jn, LC-264, KANJARI BORIYAVI, UTARSANDA, NADIAD, LC-278, GOTHAJ, LC-286, MAHEMDABAD AND KHEDA ROAD, LC-294, KANIJ, BAREJADI NANDEJ, GERATPUR, VATVA, KANKARIYA CABIN, AHMEDABAD Jn
A56: 21 Jun | B56: 39514 | C56: 309 | D56: 309 | E56: 0 | F56: 374182 | G56: 395426 | H56: - | I56: - | J56: 0 | K56: No | L56: 0 | M56: BAJWA, RANOLI, LC-246, VASAD, ADAS ROAD, VADOD, LC-258, ANAND Jn, LC-264, KANJARI BORIYAVI, UTARSANDA, NADIAD, LC-278, GOTHAJ, LC-286, MAHEMDABAD AND KHEDA ROAD, LC-294, KANIJ, BAREJADI NANDEJ, GERATPUR, VATVA, KANKARIYA CABIN, AHMEDABAD Jn
A57: 21 Jun | B57: 43660 | C57: 248 | D57: 164 | E57: 0 | F57: 2499972 | G57: 2500602 | H57: - | I57: - | J57: 0 | K57: No | L57: 0 | M57: BAJWA, RANOLI, LC-246, VASAD, ADAS ROAD, VADOD, LC-258, ANAND Jn, LC-264, KANJARI BORIYAVI, UTARSANDA, NADIAD, LC-278, GOTHAJ, LC-286, MAHEMDABAD AND KHEDA ROAD, LC-294, KANIJ, BAREJADI NANDEJ, GERATPUR, VATVA, KANKARIYA CABIN, AHMEDABAD Jn
A58: 21 Jun | B58: 43922 | C58: 17 | D58: 0 | E58: 0 | F58: - | G58: - | H58: - | I58: - | J58: 0 | K58: No | L58: 0 | M58: BAJWA, RANOLI, LC-246, VASAD, ADAS ROAD, VADOD, LC-258, ANAND Jn, LC-264, KANJARI BORIYAVI, UTARSANDA, NADIAD, LC-278, GOTHAJ, LC-286, MAHEMDABAD AND KHEDA ROAD, LC-294, KANIJ, BAREJADI NANDEJ, GERATPUR, VATVA, KANKARIYA CABIN, AHMEDABAD Jn
A59: 22 Jun | B59: 30314 | C59: 4708 | D59: 4708 | E59: 3823 | F59: 375215 | G59: 494964 | H59: 400398 | I59: 494312 | J59: =(I59-H59)/1000 | K59: Yes | L59: 23 | M59: - (full trip)
A60: 22 Jun | B60: 30476 | C60: 5790 | D60: 5790 | E60: 4938 | F60: 361584 | G60: 495769 | H60: 400399 | I60: 494306 | J60: =(I60-H60)/1000 | K60: Yes | L60: 23 | M60: - (full trip)
A61: 22 Jun | B61: 30507 | C61: 5846 | D61: 5846 | E61: 5377 | F61: 398301 | G61: 495784 | H61: 400399 | I61: 494311 | J61: =(I61-H61)/1000 | K61: Yes | L61: 23 | M61: - (full trip)
A62: 22 Jun | B62: 30531 | C62: 4331 | D62: 4331 | E62: 3901 | F62: 396975 | G62: 494984 | H62: 400401 | I62: 494311 | J62: =(I62-H62)/1000 | K62: Yes | L62: 23 | M62: - (full trip)
A63: 22 Jun | B63: 33715 | C63: 12469 | D63: 12469 | E63: 10374 | F63: 361614 | G63: 495716 | H63: 400406 | I63: 494311 | J63: =(I63-H63)/1000 | K63: Yes | L63: 23 | M63: - (full trip)
A64: 22 Jun | B64: 37163 | C64: 5917 | D64: 5917 | E64: 4206 | F64: 360968 | G64: 494966 | H64: 400399 | I64: 494310 | J64: =(I64-H64)/1000 | K64: Yes | L64: 23 | M64: - (full trip)
A65: 22 Jun | B65: 37793 | C65: 6748 | D65: 6748 | E65: 5400 | F65: 363506 | G65: 495466 | H65: 400400 | I65: 494309 | J65: =(I65-H65)/1000 | K65: Yes | L65: 23 | M65: - (full trip)
A66: 22 Jun | B66: 37887 | C66: 6274 | D66: 6274 | E66: 5320 | F66: 369874 | G66: 494979 | H66: 400404 | I66: 494310 | J66: =(I66-H66)/1000 | K66: Yes | L66: 23 | M66: - (full trip)
A67: 22 Jun | B67: 37287 | C67: 7013 | D67: 7013 | E67: 5971 | F67: 369973 | G67: 495595 | H67: 400408 | I67: 494312 | J67: =(I67-H67)/1000 | K67: Yes | L67: 23 | M67: - (full trip)
A68: 22 Jun | B68: 37337 | C68: 6420 | D68: 6420 | E68: 5102 | F68: 370065 | G68: 494968 | H68: 400413 | I68: 494311 | J68: =(I68-H68)/1000 | K68: Yes | L68: 23 | M68: - (full trip)
A69: 22 Jun | B69: 37453 | C69: 5204 | D69: 5199 | E69: 3781 | F69: 370240 | G69: 494980 | H69: 400413 | I69: 494312 | J69: =(I69-H69)/1000 | K69: Yes | L69: 23 | M69: - (full trip)
A70: 22 Jun | B70: 39014 | C70: 4561 | D70: 4561 | E70: 4230 | F70: 398125 | G70: 495807 | H70: 400409 | I70: 494311 | J70: =(I70-H70)/1000 | K70: Yes | L70: 23 | M70: - (full trip)
... A100: 22 Jun | B100: 39467 | C100: 1560 | D100: 1531 | E100: 394 | F100: 370007 | G100: 402392 | H100: 400405 | I100: 402392 | J100: =(I100-H100)/1000 | K100: Yes | L100: 1 | M100: RANOLI, LC-246, VASAD, ADAS ROAD, VADOD, LC-258, ANAND Jn, LC-264, KANJARI BORIYAVI, UTARSANDA, NADIAD, LC-278, GOTHAJ, LC-286, MAHEMDABAD AND KHEDA ROAD, LC-294, KANIJ, BAREJADI NANDEJ, GERATPUR, VATVA, KANKARIYA CABIN, AHMEDABAD Jn
...

Sheet Methodology
B1: Methodology
B3: Excluded | C3: Loco-days with 0 km in the section (abs never inside the section, i.e. no section travel) are dropped from the report, unless they completed a trip.
B4: No of Trips | C4: A direction-run covering within 5 km of its line length (DN 93.91 / UP 93.91 km) = one FULL trip; out-and-back = 2. A loco with >=1 full trip is 'valid' (its EBs count as Valid). KM Verification lists each loco-day's stations passed / not passed.
B5: Total KMs Run on Kavach | C5: Section coverage per loco = how far it travelled across the section = (max - min) of its abs within the section limits (400398-494312). Capped at the section length; 0 if the loco never reported inside the section.
B6: Availability (FS+OS) | C6: Packets in FS or OnSight ÷ all packets (all modes) × 100.
B7: Total EB | C7: EB events in LReg brake status; one continuous hold = 1 (lost-packet gaps bridged, new event only at a real release). Split into Valid (trip locos) / Non-Valid.
B8: Mode Degradation | C8: Each transition into LS or SR from a less-degraded mode, on the merged LReq+LReg timeline. Counts FS/OS/Trip/PostTrip/Standby→LS or SR and LS→SR; excludes NonLeading→LS/SR, FS→OS, recovery (→FS), spells outside the section, and spells with a >60s packet gap (loco stabled / out of coverage).
B9: EB diagnostics | C9: Speed at EB + flag a PG issue only if it jumps >=6 km/h vs the IMMEDIATELY preceding packet AND that packet is within 2 s of the EB (if the previous packet was lost, no PG flag); MA from SReg 'MA wrt Sig' + flag drop >500; Emergency from LReg.
B10: Ratios | C10: per Trip=÷Trips; per KM=÷KM; per 100 KM=÷KM×100; per Trip per 1000 KM=÷(Trips×KM/1000); per Trip per 100 KM=÷(Trips×KM/100).
